Workbook

Sheet Synthese
A1: Joueur | B1: Sélection | C1: Club (saison) | D1: Matchs | E1: Buts | F1: Passes | G1: Contributions | H1: Buts / match | I1: Lignes confirmées | J1: Lignes arbitrées | K1: Lignes conservées | L1: Statut global
A2: Kylian Mbappé | B2: France | C2: Real Madrid | D2: =SUMIFS(Detail!$D$2:$D$64,Detail!$A$2:$A$64,A2) -> 56 | E2: =SUMIFS(Detail!$E$2:$E$64,Detail!$A$2:$A$64,A2) -> 57 | F2: =SUMIFS(Detail!$F$2:$F$64,Detail!$A$2:$A$64,A2) -> 10 | G2: =E2+F2 -> 67 | H2: =IFERROR(ROUND(E2/D2,2),0) -> 1.02 | I2: =COUNTIFS(Detail!$A$2:$A$64,A2,Detail!$G$2:$G$64,"Confirmé*") -> 4 | J2: =COUNTIFS(Detail!$A$2:$A$64,A2,Detail!$G$2:$G$64,"Arbitré*") -> 0 | K2: =COUNTIFS(Detail!$A$2:$A$64,A2,Detail!$G$2:$G$64,"Conservé*") -> 0 | L2: verified
A3: Ousmane Dembélé | B3: France | C3: Paris Saint-Germain | D3: =SUMIFS(Detail!$D$2:$D$64,Detail!$A$2:$A$64,A3) -> 49 | E3: =SUMIFS(Detail!$E$2:$E$64,Detail!$A$2:$A$64,A3) -> 26 | F3: =SUMIFS(Detail!$F$2:$F$64,Detail!$A$2:$A$64,A3) -> 11 | G3: =E3+F3 -> 37 | H3: =IFERROR(ROUND(E3/D3,2),0) -> 0.53 | I3: =COUNTIFS(Detail!$A$2:$A$64,A3,Detail!$G$2:$G$64,"Confirmé*") -> 2 | J3: =COUNTIFS(Detail!$A$2:$A$64,A3,Detail!$G$2:$G$64,"Arbitré*") -> 1 | K3: =COUNTIFS(Detail!$A$2:$A$64,A3,Detail!$G$2:$G$64,"Conservé*") -> 5 | L3: verified-with-arbitration
A4: Michael Olise | B4: France | C4: Bayern Munich | D4: =SUMIFS(Detail!$D$2:$D$64,Detail!$A$2:$A$64,A4) -> 65 | E4: =SUMIFS(Detail!$E$2:$E$64,Detail!$A$2:$A$64,A4) -> 24 | F4: =SUMIFS(Detail!$F$2:$F$64,Detail!$A$2:$A$64,A4) -> 35 | G4: =E4+F4 -> 59 | H4: =IFERROR(ROUND(E4/D4,2),0) -> 0.37 | I4: =COUNTIFS(Detail!$A$2:$A$64,A4,Detail!$G$2:$G$64,"Confirmé*") -> 3 | J4: =COUNTIFS(Detail!$A$2:$A$64,A4,Detail!$G$2:$G$64,"Arbitré*") -> 0 | K4: =COUNTIFS(Detail!$A$2:$A$64,A4,Detail!$G$2:$G$64,"Conservé*") -> 3 | L4: verified
A5: Rodri | B5: Espagne | C5: Manchester City | D5: =SUMIFS(Detail!$D$2:$D$64,Detail!$A$2:$A$64,A5) -> 43 | E5: =SUMIFS(Detail!$E$2:$E$64,Detail!$A$2:$A$64,A5) -> 2 | F5: =SUMIFS(Detail!$F$2:$F$64,Detail!$A$2:$A$64,A5) -> 0 | G5: =E5+F5 -> 2 | H5: =IFERROR(ROUND(E5/D5,2),0) -> 0.05 | I5: =COUNTIFS(Detail!$A$2:$A$64,A5,Detail!$G$2:$G$64,"Confirmé*") -> 1 | J5: =COUNTIFS(Detail!$A$2:$A$64,A5,Detail!$G$2:$G$64,"Arbitré*") -> 0 | K5: =COUNTIFS(Detail!$A$2:$A$64,A5,Detail!$G$2:$G$64,"Conservé*") -> 5 | L5: verified
A6: Lamine Yamal | B6: Espagne | C6: FC Barcelone | D6: =SUMIFS(Detail!$D$2:$D$64,Detail!$A$2:$A$64,A6) -> 55 | E6: =SUMIFS(Detail!$E$2:$E$64,Detail!$A$2:$A$64,A6) -> 25 | F6: =SUMIFS(Detail!$F$2:$F$64,Detail!$A$2:$A$64,A6) -> 16 | G6: =E6+F6 -> 41 | H6: =IFERROR(ROUND(E6/D6,2),0) -> 0.45 | I6: =COUNTIFS(Detail!$A$2:$A$64,A6,Detail!$G$2:$G$64,"Confirmé*") -> 2 | J6: =COUNTIFS(Detail!$A$2:$A$64,A6,Detail!$G$2:$G$64,"Arbitré*") -> 0 | K6: =COUNTIFS(Detail!$A$2:$A$64,A6,Detail!$G$2:$G$64,"Conservé*") -> 1 | L6: verified
A7: Jude Bellingham | B7: Angleterre | C7: Real Madrid | D7: =SUMIFS(Detail!$D$2:$D$64,Detail!$A$2:$A$64,A7) -> 41 | E7: =SUMIFS(Detail!$E$2:$E$64,Detail!$A$2:$A$64,A7) -> 13 | F7: =SUMIFS(Detail!$F$2:$F$64,Detail!$A$2:$A$64,A7) -> 4 | G7: =E7+F7 -> 17 | H7: =IFERROR(ROUND(E7/D7,2),0) -> 0.32 | I7: =COUNTIFS(Detail!$A$2:$A$64,A7,Detail!$G$2:$G$64,"Confirmé*") -> 1 | J7: =COUNTIFS(Detail!$A$2:$A$64,A7,Detail!$G$2:$G$64,"Arbitré*") -> 1 | K7: =COUNTIFS(Detail!$A$2:$A$64,A7,Detail!$G$2:$G$64,"Conservé*") -> 4 | L7: verified-with-arbitration
A8: Harry Kane | B8: Angleterre | C8: Bayern Munich | D8: =SUMIFS(Detail!$D$2:$D$64,Detail!$A$2:$A$64,A8) -> 64 | E8: =SUMIFS(Detail!$E$2:$E$64,Detail!$A$2:$A$64,A8) -> 72 | F8: =SUMIFS(Detail!$F$2:$F$64,Detail!$A$2:$A$64,A8) -> 8 | G8: =E8+F8 -> 80 | H8: =IFERROR(ROUND(E8/D8,2),0) -> 1.13 | I8: =COUNTIFS(Detail!$A$2:$A$64,A8,Detail!$G$2:$G$64,"Confirmé*") -> 5 | J8: =COUNTIFS(Detail!$A$2:$A$64,A8,Detail!$G$2:$G$64,"Arbitré*") -> 0 | K8: =COUNTIFS(Detail!$A$2:$A$64,A8,Detail!$G$2:$G$64,"Conservé*") -> 1 | L8: verified
A9: Lionel Messi | B9: Argentine | C9: Inter Miami | D9: =SUMIFS(Detail!$D$2:$D$64,Detail!$A$2:$A$64,A9) -> 49 | E9: =SUMIFS(Detail!$E$2:$E$64,Detail!$A$2:$A$64,A9) -> 48 | F9: =SUMIFS(Detail!$F$2:$F$64,Detail!$A$2:$A$64,A9) -> 34 | G9: =E9+F9 -> 82 | H9: =IFERROR(ROUND(E9/D9,2),0) -> 0.98 | I9: =COUNTIFS(Detail!$A$2:$A$64,A9,Detail!$G$2:$G$64,"Confirmé*") -> 6 | J9: =COUNTIFS(Detail!$A$2:$A$64,A9,Detail!$G$2:$G$64,"Arbitré*") -> 0 | K9: =COUNTIFS(Detail!$A$2:$A$64,A9,Detail!$G$2:$G$64,"Conservé*") -> 0 | L9: verified
A10: Khvicha Kvaratskhelia | B10: Géorgie | C10: Paris Saint-Germain | D10: =SUMIFS(Detail!$D$2:$D$64,Detail!$A$2:$A$64,A10) -> 54 | E10: =SUMIFS(Detail!$E$2:$E$64,Detail!$A$2:$A$64,A10) -> 20 | F10: =SUMIFS(Detail!$F$2:$F$64,Detail!$A$2:$A$64,A10) -> 10 | G10: =E10+F10 -> 30 | H10: =IFERROR(ROUND(E10/D10,2),0) -> 0.37 | I10: =COUNTIFS(Detail!$A$2:$A$64,A10,Detail!$G$2:$G$64,"Confirmé*") -> 1 | J10: =COUNTIFS(Detail!$A$2:$A$64,A10,Detail!$G$2:$G$64,"Arbitré*") -> 1 | K10: =COUNTIFS(Detail!$A$2:$A$64,A10,Detail!$G$2:$G$64,"Conservé*") -> 5 | L10: verified-with-arbitration
A11: Erling Haaland | B11: Norvège | C11: Manchester City | D11: =SUMIFS(Detail!$D$2:$D$64,Detail!$A$2:$A$64,A11) -> 62 | E11: =SUMIFS(Detail!$E$2:$E$64,Detail!$A$2:$A$64,A11) -> 57 | F11: =SUMIFS(Detail!$F$2:$F$64,Detail!$A$2:$A$64,A11) -> 9 | G11: =E11+F11 -> 66 | H11: =IFERROR(ROUND(E11/D11,2),0) -> 0.92 | I11: =COUNTIFS(Detail!$A$2:$A$64,A11,Detail!$G$2:$G$64,"Confirmé*") -> 4 | J11: =COUNTIFS(Detail!$A$2:$A$64,A11,Detail!$G$2:$G$64,"Arbitré*") -> 1 | K11: =COUNTIFS(Detail!$A$2:$A$64,A11,Detail!$G$2:$G$64,"Conservé*") -> 1 | L11: verified-with-arbitration
A12: TOTAL | D12: =SUM(D2:D11) -> 538 | E12: =SUM(E2:E11) -> 344 | F12: =SUM(F2:F11) -> 137 | G12: =SUM(G2:G11) -> 481 | I12: =SUM(I2:I11) -> 29 | J12: =SUM(J2:J11) -> 4 | K12: =SUM(K2:K11) -> 25
A14: Passes : « n.r. » = non renseigné pour la compétition ; les totaux de passes sont donc des minimums (affichés « + » sur le site).
A15: Totaux calculés par formule depuis l'onglet Detail.

Sheet Detail
A1: Joueur | B1: Compétition | C1: Catégorie | D1: Matchs | E1: Buts | F1: Passes | G1: Statut | H1: Source | I1: Note
A2: Kylian Mbappé | B2: LaLiga | C2: Championnat | D2: 31 | E2: 25 | F2: 5 | G2: Confirmé (source officielle) | H2: Real Madrid / Goal (Pichichi 25) | I2: 31 m / 25 b / 5 p
A3: Kylian Mbappé | B3: Copa del Rey | C3: Coupe nationale | D3: 1 | E3: 2 | F3: 0 | G3: Déduit d'un total officiel | H3: Real Madrid : 44 m / 42 b toutes compétitions
A4: Kylian Mbappé | B4: Ligue des champions | C4: Coupe continentale | D4: 11 | E4: 15 | F4: 1 | G4: Confirmé (source officielle) | H4: Real Madrid : meilleur buteur LDC 15 b en 11 m
A5: Kylian Mbappé | B5: Supercoupe d'Espagne | C5: Supercoupes / autres | D5: 1 | E5: 0 | F5: n.r. | G5: Déduit d'un total officiel | H5: Real Madrid : 44 m / 42 b toutes compétitions
A6: Kylian Mbappé | B6: Coupe du monde 2026 | C6: Coupe du monde | D6: 8 | E6: 10 | F6: 4 | G6: Confirmé (médias concordants) | H6: FIFA via Foot Mercato, Goal (Soulier d'or 10 b) | I6: 4 passes : source unique (Foot Africa)
A7: Kylian Mbappé | B7: Qualifications Coupe du monde (UEFA) | C7: Qualifications Coupe du monde | D7: 4 | E7: 5 | F7: n.r. | G7: Confirmé (médias concordants) | H7: Classement buteurs qualifs UEFA : 5 b | I7: Buts : Ukraine, Islande, Azerbaïdjan, Ukraine ×2 = 5 en 4 matchs
A8: Ousmane Dembélé | B8: Ligue 1 | C8: Championnat | D8: 22 | E8: 10 | F8: 7 | G8: Arbitré (valeur la plus cohérente) | H8: UNFP (11/05/2026) : 20 m / 10 b / 6 p | I8: 22/10/7 conservé : UNFP au 11/05 avant 2 journées ; a joué le 17/05
A9: Ousmane Dembélé | B9: Coupe de France | C9: Coupe nationale | D9: 2 | E9: 1 | F9: n.r. | G9: Conservé (cohérent, non contredit) | H9: PSG éliminé en 16es (Paris FC) | I9: Valeur d'origine, cohérente avec les totaux et le calendrier
A10: Ousmane Dembélé | B10: Ligue des champions | C10: Coupe continentale | D10: 13 | E10: 8 | F10: 2 | G10: Conservé (cohérent, non contredit) | H10: — | I10: Total club 20 b confirmé (Wikipedia PSG)
A11: Ousmane Dembélé | B11: Trophée des champions | C11: Trophée des champions | D11: 1 | E11: 1 | F11: n.r. | G11: Confirmé (médias concordants) | H11: Sports Mole : but à la 13e vs Marseille
A12: Ousmane Dembélé | B12: Supercoupe de l'UEFA | C12: Supercoupe de l'UEFA | D12: 1 | E12: 0 | F12: n.r. | G12: Conservé (cohérent, non contredit) | H12: — | I12: Valeur d'origine, cohérente avec les totaux et le calendrier
A13: Ousmane Dembélé | B13: Coupe intercontinentale | C13: Coupe intercontinentale | D13: 1 | E13: 0 | F13: n.r. | G13: Conservé (cohérent, non contredit) | H13: — | I13: Valeur d'origine, cohérente avec les totaux et le calendrier
A14: Ousmane Dembélé | B14: Coupe du monde 2026 | C14: Coupe du monde | D14: 8 | E14: 6 | F14: 2 | G14: Confirmé (médias concordants) | H14: Reconstitué : Irak 1, Norvège 3, Maroc 1, Angleterre 1 | I14: Passes non vérifiées
A15: Ousmane Dembélé | B15: Qualifications Coupe du monde (UEFA) | C15: Qualifications Coupe du monde | D15: 1 | E15: 0 | F15: n.r. | G15: Conservé (cohérent, non contredit) | H15: — | I15: Valeur d'origine, cohérente avec les totaux et le calendrier
A16: Michael Olise | B16: Bundesliga | C16: Championnat | D16: 32 | E16: 15 | F16: 19 | G16: Confirmé (source officielle) | H16: DFL / Bundesliga.com : 32 m / 15 b / 19 p
A17: Michael Olise | B17: Coupe d'Allemagne | C17: Coupe nationale | D17: 6 | E17: 2 | F17: 1 | G17: Conservé (cohérent, non contredit) | H17: — | I17: Valeur d'origine, cohérente avec les totaux et le calendrier
A18: Michael Olise | B18: Ligue des champions | C18: Coupe continentale | D18: 13 | E18: 5 | F18: 8 | G18: Confirmé (médias concordants) | H18: Bundesliga.com : 8 passes (co-meilleur passeur) | I18: Buts et matchs non vérifiés
A19: Michael Olise | B19: Supercoupe d'Allemagne | C19: Supercoupes / autres | D19: 1 | E19: 0 | F19: n.r. | G19: Conservé (cohérent, non contredit) | H19: — | I19: Valeur d'origine, cohérente avec les totaux et le calendrier
A20: Michael Olise | B20: Coupe du monde 2026 | C20: Coupe du monde | D20: 8 | E20: 0 | F20: 7 | G20: Confirmé (médias concordants) | H20: beIN / Afrik : meilleur passeur, 7 p (record)
A21: Michael Olise | B21: Qualifications Coupe du monde (UEFA) | C21: Qualifications Coupe du monde | D21: 5 | E21: 2 | F21: n.r. | G21: Conservé (cohérent, non contredit) | H21: — | I21: Valeur d'origine, cohérente avec les totaux et le calendrier
A22: Rodri | B22: Premier League | C22: Championnat | D22: 21 | E22: 1 | F22: 0 | G22: Confirmé (médias concordants) | H22: Rotowire / Foot Africa : 21 m, 1 b
A23: Rodri | B23: FA Cup | C23: Coupe nationale | D23: 4 | E23: 1 | F23: n.r. | G23: Conservé (cohérent, non contredit) | H23: — | I23: Valeur d'origine, cohérente avec les totaux et le calendrier
A24: Rodri | B24: EFL Cup | C24: Coupe de la Ligue | D24: 3 | E24: 0 | F24: n.r. | G24: Conservé (cohérent, non contredit) | H24: — | I24: Valeur d'origine, cohérente avec les totaux et le calendrier
A25: Rodri | B25: Ligue des champions | C25: Coupe continentale | D25: 5 | E25: 0 | F25: n.r. | G25: Conservé (cohérent, non contredit) | H25: — | I25: Valeur d'origine, cohérente avec les totaux et le calendrier
A26: Rodri | B26: Coupe du monde 2026 | C26: Coupe du monde | D26: 8 | E26: 0 | F26: 0 | G26: Conservé (cohérent, non contredit) | H26: Espagne : 8 matchs jusqu'au titre | I26: Valeur d'origine, cohérente avec les totaux et le calendrier
A27: Rodri | B27: Qualifications Coupe du monde (UEFA) | C27: Qualifications Coupe du monde | D27: 2 | E27: 0 | F27: n.r. | G27: Conservé (cohérent, non contredit) | H27: — | I27: Valeur d'origine, cohérente avec les totaux et le calendrier
A28: Lamine Yamal | B28: LaLiga | C28: Championnat | D28: 28 | E28: 16 | F28: 12 | G28: Confirmé (source officielle) | H28: LaLiga : 16 b / 12 p | I28: Matchs non vérifiés
A29: Lamine Yamal | B29: Copa del Rey | C29: Coupe nationale | D29: 5 | E29: 2 | F29: n.r. | G29: Déduit d'un total officiel | H29: ESPN : 24 b toutes compétitions en club
A30: Lamine Yamal | B30: Ligue des champions | C30: Coupe continentale | D30: 10 | E30: 6 | F30: 4 | G30: Déduit d'un total officiel | H30: ESPN : 24 b toutes compétitions en club
A31: Lamine Yamal | B31: Supercoupe d'Espagne | C31: Supercoupes / autres | D31: 2 | E31: 0 | F31: n.r. | G31: Déduit d'un total officiel | H31: ESPN : 24 b toutes compétitions en club
A32: Lamine Yamal | B32: Coupe du monde 2026 | C32: Coupe du monde | D32: 8 | E32: 1 | F32: 0 | G32: Confirmé (médias concordants) | H32: Rotowire : 1 b, 0 p
A33: Lamine Yamal | B33: Qualifications Coupe du monde (UEFA) | C33: Qualifications Coupe du monde | D33: 2 | E33: 0 | F33: n.r. | G33: Conservé (cohérent, non contredit) | H33: — | I33: Valeur d'origine, cohérente avec les totaux et le calendrier
A34: Jude Bellingham | B34: LaLiga | C34: Championnat | D34: 19 | E34: 4 | F34: 3 | G34: Arbitré (valeur la plus cohérente) | H34: Soccerway : 19 m / 4 b / 3 p (valeur retenue) | I34: Ancien 28/6/4 incompatible avec 2 blessures
A35: Jude Bellingham | B35: Copa del Rey | C35: Coupe nationale | D35: 1 | E35: 0 | F35: n.r. | G35: Conservé (cohérent, non contredit) | H35: Real éliminé en 8es (Albacete) | I35: Valeur d'origine, cohérente avec les totaux et le calendrier
A36: Jude Bellingham | B36: Ligue des champions | C36: Coupe continentale | D36: 9 | E36: 2 | F36: n.r. | G36: Conservé (cohérent, non contredit) | H36: 1 b confirmé (Juventus 22/10/2025) ; absent barrages et 8es | I36: Valeur d'origine, cohérente avec les totaux et le calendrier
A37: Jude Bellingham | B37: Supercoupe d'Espagne | C37: Supercoupes / autres | D37: 2 | E37: 0 | F37: n.r. | G37: Conservé (cohérent, non contredit) | H37: Real finaliste de la Supercopa | I37: Valeur d'origine, cohérente avec les totaux et le calendrier
A38: Jude Bellingham | B38: Coupe du monde 2026 | C38: Coupe du monde | D38: 8 | E38: 7 | F38: 1 | G38: Confirmé (médias concordants) | H38: Foot Mercato : 7 b
A39: Jude Bellingham | B39: Qualifications Coupe du monde (UEFA) | C39: Qualifications Coupe du monde | D39: 2 | E39: 0 | F39: n.r. | G39: Conservé (cohérent, non contredit) | H39: — | I39: Valeur d'origine, cohérente avec les totaux et le calendrier
A40: Harry Kane | B40: Bundesliga | C40: Championnat | D40: 31 | E40: 36 | F40: 5 | G40: Confirmé (source officielle) | H40: Bundesliga.com : 31 m / 36 b / 5 p
...

Sheet Distinctions
A1: Joueur | B1: Type | C1: Distinction | D1: Statut
A2: Kylian Mbappé | B2: Individuelle | C2: Meilleur buteur — Ligue des champions | D2: Confirmé (source officielle)
A3: Kylian Mbappé | B3: Individuelle | C3: Meilleur buteur — Liga | D3: Confirmé (source officielle)
A4: Kylian Mbappé | B4: Individuelle | C4: Meilleur buteur — Coupe du monde | D4: Confirmé (source officielle)
A5: Kylian Mbappé | B5: Individuelle | C5: 3ème meilleur joueur — Coupe du monde | D5: Confirmé (source officielle)
A6: Ousmane Dembélé | B6: Collective | C6: Ligue 1 | D6: Confirmé (source officielle)
A7: Ousmane Dembélé | B7: Collective | C7: Trophée des champions | D7: Confirmé (source officielle)
A8: Ousmane Dembélé | B8: Collective | C8: Ligue des champions | D8: Confirmé (source officielle)
A9: Ousmane Dembélé | B9: Collective | C9: Supercoupe de l'UEFA | D9: Confirmé (source officielle)
A10: Ousmane Dembélé | B10: Collective | C10: Coupe intercontinentale | D10: Confirmé (source officielle)
A11: Ousmane Dembélé | B11: Individuelle | C11: Meilleur joueur — Ligue 1 | D11: Confirmé (source officielle)
A12: Michael Olise | B12: Collective | C12: Bundesliga | D12: Confirmé (source officielle)
... A54: Erling Haaland | B54: Individuelle | C54: Meilleur buteur — Coupe du monde (qualifications) | D54: Confirmé (médias concordants)

Sheet Methodologie
A1: Période | B1: 3 août 2025 – 19 juillet 2026 ; club + sélection ; matchs amicaux exclus
A2: Exception | B2: Messi : MLS comptée sur la saison 2025 complète (régulière + playoffs), Leagues Cup incluse
A3: Source des données | B3: Wikipédia (CC BY-SA 4.0) ; passes : ESPN (relevé manuel) ; corrections : sources officielles
A4: Sources de contrôle | B4: UEFA, DFL/Bundesliga.com, LaLiga, Premier League, clubs (Real Madrid, Bayern, Man City, Inter Miami), Concacaf, UNFP, Soccerway, FotMob, The Analyst (Opta), presse (Foot Mercato, beIN, Goal, ESPN, NBC)
A5: Date du contrôle | B5: 24/09/2026
A6: Corrections appliquées | B6: Bellingham Liga 28/6/4 → 19/4/3 ; Messi MLS passes 20 → 19 ; Yamal Liga passes 11 → 12 ; Olise LDC passes 6 → 8 ; Mbappé CdM passes n.r. → 4 ; retrait « 2ème meilleur passeur LDC » (Kvaratskhelia) ; Kvaratskhelia L1 buts 8 → 7 ; Haaland FA Cup passes n.r. → 1
A7: Arbitrages | B7: Dembélé L1 conservée (22/10/7) ; Kvaratskhelia L1 7 b ; Haaland FA Cup 4 m + 1 p ; Bellingham L1 19/4/3
A8: Réserve méthodologique | B8: Les passes décisives varient selon le fournisseur (Opta, Transfermarkt, organisateurs). Les chiffres mêlent ici organisateurs et ESPN : pour un contrôle strict, adopter une seule base de référence et la citer.
A9: Légende des statuts | B9: Confirmé (source officielle) · Confirmé (médias concordants) · Déduit d'un total officiel · Cohérent / plausible · Écart entre sources · Non vérifié · Arbitré (valeur la plus cohérente) · Conservé (cohérent, non contredit)
A10: Règle pour les lignes non vérifiables | B10: Valeur d'origine conservée si aucune source ne la contredit ET si elle est cohérente avec les totaux officiels et le calendrier (qualifications, blessures, éliminations). Aucune valeur n'a été inventée.
